Workbook

Sheet Resumen
A1: RESUMEN DE CUANTIFICACIÓN – MUROS SÓTANO
A2: Proyecto: Casa JPS – Sótano | Planos S-1 (DXF), S-7 y S-8 (PDF) | Rev. 1 – 2026-10-12 | Unidades: m, m²
D3: ml | E3: m | F3: m² | G3: m² | H3: m²
A4: No. | B4: Elemento | C4: Espesor | D4: Longitud | E4: Altura total | F4: Área bruta | G4: (−) Vanos | H4: Área neta | I4: Observaciones
A5: A. MUROS DE EDIFICACIÓN
A6: 1 | B6: Muro block 0.20 que carga | C6: 0.2 | D6: =SUMIF(Muros!$C$5:$C$68,B6,Muros!$F$5:$F$68) | E6: =IF(Parámetros!$B$5="","pendiente",Parámetros!$B$5) | F6: =IF(Parámetros!$B$5="","pendiente",D6*Parámetros!$B$5) | G6: =IF(COUNTIF(Vanos!$C$5:$C$9,B6)=0,0,IF(Parámetros!$B$7="","pendiente",SUMIF(Vanos!$C$5:$C$9,B6,Vanos!$D$5:$D$9)*Parámetros!$B$7)) | H6: =IF(OR(F6="pendiente",G6="pendiente"),"pendiente",F6-G6)
A7: 2 | B7: Muro block 0.15 que carga | C7: 0.15 | D7: =SUMIF(Muros!$C$5:$C$68,B7,Muros!$F$5:$F$68) | E7: =IF(Parámetros!$B$5="","pendiente",Parámetros!$B$5) | F7: =IF(Parámetros!$B$5="","pendiente",D7*Parámetros!$B$5) | G7: =IF(COUNTIF(Vanos!$C$5:$C$9,B7)=0,0,IF(Parámetros!$B$7="","pendiente",SUMIF(Vanos!$C$5:$C$9,B7,Vanos!$D$5:$D$9)*Parámetros!$B$7)) | H7: =IF(OR(F7="pendiente",G7="pendiente"),"pendiente",F7-G7)
A8: 3 | B8: Muro block 0.15 que no carga | C8: 0.15 | D8: =SUMIF(Muros!$C$5:$C$68,B8,Muros!$F$5:$F$68) | E8: =IF(Parámetros!$B$5="","pendiente",Parámetros!$B$5) | F8: =IF(Parámetros!$B$5="","pendiente",D8*Parámetros!$B$5) | G8: =IF(COUNTIF(Vanos!$C$5:$C$9,B8)=0,0,IF(Parámetros!$B$7="","pendiente",SUMIF(Vanos!$C$5:$C$9,B8,Vanos!$D$5:$D$9)*Parámetros!$B$7)) | H8: =IF(OR(F8="pendiente",G8="pendiente"),"pendiente",F8-G8) | I8: Incluye M-40, M-41, M-42 y M-49 (11.63 ml) paralelos al MC1 → RFI
A9: B. MURO DE CONTENCIÓN MC1 (grupo independiente)
A10: 4 | B10: Muro MC1 block doble hilada 0.15+0.15 | C10: 0.3 | D10: =SUMIF(Muros!$C$5:$C$68,B10,Muros!$F$5:$F$68) | E10: =IF(Parámetros!$B$6="","pendiente",Parámetros!$B$6) | F10: =IF(Parámetros!$B$6="","pendiente",D10*Parámetros!$B$6) | G10: =IF(COUNTIF(Vanos!$C$5:$C$9,B10)=0,0,IF(Parámetros!$B$7="","pendiente",SUMIF(Vanos!$C$5:$C$9,B10,Vanos!$D$5:$D$9)*Parámetros!$B$7)) | H10: =IF(OR(F10="pendiente",G10="pendiente"),"pendiente",F10-G10) | I10: Excluye huecos de columnas C; ver Pendientes
A12: Longitud = eje de cada tramo de block dibujado en planta; en vanos el muro corre continuo a ALTURA TOTAL y el área del vano se deduce aparte (hoja Vanos).
A13: Columnas, mochetas y huecos de 0.10–0.85 m entre tramos no se cuentan como muro (16 huecos, ver Pendientes).

Sheet Parámetros
A1: PARÁMETROS
A2: Proyecto: Casa JPS – Sótano | Planos S-1 (DXF), S-7 y S-8 (PDF) | Rev. 1 – 2026-10-12 | Unidades: m, m² | Verde = medido en cortes | Amarillo = supuesto editable
A4: Parámetro | B4: Valor | C4: Unidad | D4: Fuente / estado
A5: Altura total muros de edificación (sótano) | B5: 4.3 | C5: m | D5: Corona CC1 −4.65 a NPT −0.35 (losa). Medido en S-7 Secc. A/B y S-8 Secc. C/D
A6: Altura total muro MC1 | B6: 4.3 | C6: m | D6: Corona MC1 −4.65 a NPT −0.35 (cara sup. SR1 = losa). S-7 A/B, S-8 C/D
A7: Altura de vanos de puerta | B7: 2.1 | C7: m | D7: [Supuesto] puerta estándar; no hay plano arquitectónico. SOLO para deducir el vano, el muro va a altura total
A9: Niveles y soleras dentro de la altura total (S-7 / S-8, medidos a escala ±0.01 m)
A10: NPT losa sobre sótano | B10: −0.35 | D10: S-7/S-8; zona con losa en NPT 0.00 entre ejes 6–5 (S-7 Secc. A) → muros +0.35 m, ubicar con xref de ejes
A11: NPT piso sótano (cara sup. contrapiso) | B11: −3.85 | D11: S-7/S-8
A12: Corona de cimiento CC1 / MC1 | B12: −4.65 | D12: Lectura −4.64
A13: Fondo de cimiento | B13: −4.95 | D13: + concreto pobre 0.04 → −4.99
A14: Soleras en muro MC1 (de abajo hacia arriba) | B14: SH2, S1, S1, S8, SR1 | D14: SH2 0.30×0.20; S1 0.30×0.20; S8 0.10×0.30; SR1 0.30×0.40 (tabla de soleras S-7)
A15: Soleras en muros interiores sobre CC1 | B15: SH3, SU2, SU2, SR16 / viga | D15: SH3 0.20×0.20; SU2 block U 0.20×0.20; SR16 0.15×0.15; remate bajo vigas V8/V10
A16: Muros que arrancan sobre zapata | B16: −4.40 a −4.50 | D16: Sobre Z2/Z3/Z5/Z7/Z8 el arranque sube 0.15–0.25 m; efecto < 1 % del área total

Sheet Muros
A1: MUROS – EXTRACCIÓN POR TRAMO
A2: Proyecto: Casa JPS – Sótano | Planos S-1 (DXF), S-7 y S-8 (PDF) | Rev. 1 – 2026-10-12 | Unidades: m, m²
E3: m | F3: m | G3: m | H3: m²
A4: ID | B4: Grupo | C4: Tipo | D4: Etiqueta plano | E4: Espesor | F4: Longitud eje | G4: Altura total | H4: Área bruta | I4: Vano | J4: Inicio X,Y | K4: Fin X,Y
A5: M-54 | B5: Edificación | C5: Muro block 0.20 que carga | D5: M21 | E5: 0.2 | F5: 5.756 | G5: =IF(Parámetros!$B$5="","",Parámetros!$B$5) | H5: =IF(G5="","",F5*G5) | J5: 1.79, 1.53 | K5: 1.79, 7.29
A6: M-55 | B6: Edificación | C6: Muro block 0.20 que carga | E6: 0.2 | F6: 5.09 | G6: =IF(Parámetros!$B$5="","",Parámetros!$B$5) | H6: =IF(G6="","",F6*G6) | J6: 1.99, -3.56 | K6: 1.99, 1.53
A7: M-56 | B7: Edificación | C7: Muro block 0.20 que carga | D7: M35 | E7: 0.2 | F7: 3.178 | G7: =IF(Parámetros!$B$5="","",Parámetros!$B$5) | H7: =IF(G7="","",F7*G7) | J7: 4.14, 2.78 | K7: 5.37, 5.72
A8: M-57 | B8: Edificación | C8: Muro block 0.20 que carga | E8: 0.2 | F8: 2.281 | G8: =IF(Parámetros!$B$5="","",Parámetros!$B$5) | H8: =IF(G8="","",F8*G8) | J8: -19.59, -2.09 | K8: -21.49, -0.83
A9: M-58 | B9: Edificación | C9: Muro block 0.20 que carga | E9: 0.2 | F9: 1.84 | G9: =IF(Parámetros!$B$5="","",Parámetros!$B$5) | H9: =IF(G9="","",F9*G9) | J9: 5.56, 6.18 | K9: 6.27, 7.88
A10: M-59 | B10: Edificación | C10: Muro block 0.20 que carga | D10: M35 | E10: 0.2 | F10: 1.378 | G10: =IF(Parámetros!$B$5="","",Parámetros!$B$5) | H10: =IF(G10="","",F10*G10) | J10: 3.53, 1.31 | K10: 4.06, 2.58
A11: M-24 | B11: Edificación | C11: Muro block 0.15 que carga | E11: 0.15 | F11: 6.391 | G11: =IF(Parámetros!$B$5="","",Parámetros!$B$5) | H11: =IF(G11="","",F11*G11) | J11: -10.56, -0.59 | K11: -4.17, -0.59
A12: M-24/V-01 | B12: Edificación | C12: Muro block 0.15 que carga | E12: 0.15 | F12: 0.7 | G12: =IF(Parámetros!$B$5="","",Parámetros!$B$5) | H12: =IF(G12="","",F12*G12) | I12: V-01 | J12: -4.17, -0.59 | K12: -3.47, -0.59
A13: M-25 | B13: Edificación | C13: Muro block 0.15 que carga | D13: M5 | E13: 0.15 | F13: 6.153 | G13: =IF(Parámetros!$B$5="","",Parámetros!$B$5) | H13: =IF(G13="","",F13*G13) | J13: -11.44, 1.58 | K13: -11.44, 7.74
A14: M-26 | B14: Edificación | C14: Muro block 0.15 que carga | D14: M10 | E14: 0.15 | F14: 3.975 | G14: =IF(Parámetros!$B$5="","",Parámetros!$B$5) | H14: =IF(G14="","",F14*G14) | J14: -2.49, 1.16 | K14: 1.49, 1.16
A15: M-27 | B15: Edificación | C15: Muro block 0.15 que carga | D15: M8 | E15: 0.15 | F15: 3.5 | G15: =IF(Parámetros!$B$5="","",Parámetros!$B$5) | H15: =IF(G15="","",F15*G15) | J15: -7.84, 1.16 | K15: -4.34, 1.16
A16: M-27/V-02 | B16: Edificación | C16: Muro block 0.15 que carga | D16: M8 | E16: 0.15 | F16: 0.9 | G16: =IF(Parámetros!$B$5="","",Parámetros!$B$5) | H16: =IF(G16="","",F16*G16) | I16: V-02 | J16: -4.34, 1.16 | K16: -3.44, 1.16
A17: M-28 | B17: Edificación | C17: Muro block 0.15 que carga | D17: M7 | E17: 0.15 | F17: 3.2 | G17: =IF(Parámetros!$B$5="","",Parámetros!$B$5) | H17: =IF(G17="","",F17*G17) | J17: -14.71, 5.86 | K17: -11.51, 5.86
A18: M-29 | B18: Edificación | C18: Muro block 0.15 que carga | E18: 0.15 | F18: 1.85 | G18: =IF(Parámetros!$B$5="","",Parámetros!$B$5) | H18: =IF(G18="","",F18*G18) | J18: -5.04, -2.51 | K18: -5.04, -0.66
A19: M-30 | B19: Edificación | C19: Muro block 0.15 que carga | E19: 0.15 | F19: 1.8 | G19: =IF(Parámetros!$B$5="","",Parámetros!$B$5) | H19: =IF(G19="","",F19*G19) | J19: -11.01, 1.16 | K19: -9.21, 1.16
A20: M-30/V-03 | B20: Edificación | C20: Muro block 0.15 que carga | E20: 0.15 | F20: 0.9 | G20: =IF(Parámetros!$B$5="","",Parámetros!$B$5) | H20: =IF(G20="","",F20*G20) | I20: V-03 | J20: -9.21, 1.16 | K20: -8.31, 1.16
A21: M-31 | B21: Edificación | C21: Muro block 0.15 que carga | D21: M16 | E21: 0.15 | F21: 1.797 | G21: =IF(Parámetros!$B$5="","",Parámetros!$B$5) | H21: =IF(G21="","",F21*G21) | J21: -16.43, 5.94 | K21: -16.43, 7.74
A22: M-32 | B22: Edificación | C22: Muro block 0.15 que carga | D22: M9 | E22: 0.15 | F22: 1.696 | G22: =IF(Parámetros!$B$5="","",Parámetros!$B$5) | H22: =IF(G22="","",F22*G22) | J22: -2.69, -2.36 | K22: -2.69, -0.66
A23: M-33 | B23: Edificación | C23: Muro block 0.15 que carga | D23: M10 | E23: 0.15 | F23: 0.8 | G23: =IF(Parámetros!$B$5="","",Parámetros!$B$5) | H23: =IF(G23="","",F23*G23) | J23: -3.44, 1.16 | K23: -2.64, 1.16
A24: M-34 | B24: Edificación | C24: Muro block 0.15 que carga | D24: M9 | E24: 0.15 | F24: 0.7 | G24: =IF(Parámetros!$B$5="","",Parámetros!$B$5) | H24: =IF(G24="","",F24*G24) | J24: -3.47, -0.59 | K24: -2.77, -0.59
A25: M-35 | B25: Edificación | C25: Muro block 0.15 que carga | E25: 0.15 | F25: 0.65 | G25: =IF(Parámetros!$B$5="","",Parámetros!$B$5) | H25: =IF(G25="","",F25*G25) | J25: -5.04, -3.46 | K25: -5.04, -2.81
A26: M-36 | B26: Edificación | C26: Muro block 0.15 que carga | E26: 0.15 | F26: 0.645 | G26: =IF(Parámetros!$B$5="","",Parámetros!$B$5) | H26: =IF(G26="","",F26*G26) | J26: -10.69, 0.43 | K26: -10.69, 1.07
A27: M-37 | B27: Edificación | C27: Muro block 0.15 que carga | E27: 0.15 | F27: 0.504 | G27: =IF(Parámetros!$B$5="","",Parámetros!$B$5) | H27: =IF(G27="","",F27*G27) | J27: -2.69, -3.46 | K27: -2.69, -2.96
A28: M-37/V-04 | B28: Edificación | C28: Muro block 0.15 que carga | E28: 0.15 | F28: 0.6 | G28: =IF(Parámetros!$B$5="","",Parámetros!$B$5) | H28: =IF(G28="","",F28*G28) | I28: V-04 | J28: -2.69, -2.96 | K28: -2.69, -2.36
A29: M-38 | B29: Edificación | C29: Muro block 0.15 que carga | D29: M8 | E29: 0.15 | F29: 0.4 | G29: =IF(Parámetros!$B$5="","",Parámetros!$B$5) | H29: =IF(G29="","",F29*G29) | J29: -8.31, 1.16 | K29: -7.91, 1.16
A30: M-39 | B30: Edificación | C30: Muro block 0.15 que carga | D30: M7 | E30: 0.15 | F30: 0.4 | G30: =IF(Parámetros!$B$5="","",Parámetros!$B$5) | H30: =IF(G30="","",F30*G30) | J30: -15.26, 5.86 | K30: -14.86, 5.86
A31: M-40 | B31: Edificación | C31: Muro block 0.15 que no carga | D31: M21 | E31: 0.15 | F31: 3.873 | G31: =IF(Parámetros!$B$5="","",Parámetros!$B$5) | H31: =IF(G31="","",F31*G31) | J31: -2.41, 7.81 | K31: 1.46, 7.81
A32: M-41 | B32: Edificación | C32: Muro block 0.15 que no carga | D32: M5 | E32: 0.15 | F32: 3.238 | G32: =IF(Parámetros!$B$5="","",Parámetros!$B$5) | H32: =IF(G32="","",F32*G32) | J32: -7.75, 7.81 | K32: -4.51, 7.81
A33: M-42 | B33: Edificación | C33: Muro block 0.15 que no carga | D33: M5 | E33: 0.15 | F33: 3.138 | G33: =IF(Parámetros!$B$5="","",Parámetros!$B$5) | H33: =IF(G33="","",F33*G33) | J33: -11.25, 7.81 | K33: -8.11, 7.81
A34: M-43 | B34: Edificación | C34: Muro block 0.15 que no carga | E34: 0.15 | F34: 2.907 | G34: =IF(Parámetros!$B$5="","",Parámetros!$B$5) | H34: =IF(G34="","",F34*G34) | J34: -25.29, -6.68 | K34: -28.11, -5.98
A35: M-44 | B35: Edificación | C35: Muro block 0.15 que no carga | E35: 0.15 | F35: 2.624 | G35: =IF(Parámetros!$B$5="","",Parámetros!$B$5) | H35: =IF(G35="","",F35*G35) | J35: 1.54, -3.14 | K35: 1.54, -0.51
A36: M-45 | B36: Edificación | C36: Muro block 0.15 que no carga | E36: 0.15 | F36: 2.165 | G36: =IF(Parámetros!$B$5="","",Parámetros!$B$5) | H36: =IF(G36="","",F36*G36) | J36: -23.59, -8.13 | K36: -25.69, -7.61
A37: M-46 | B37: Edificación | C37: Muro block 0.15 que no carga | D37: M9 | E37: 0.15 | F37: 1.643 | G37: =IF(Parámetros!$B$5="","",Parámetros!$B$5) | H37: =IF(G37="","",F37*G37) | J37: -2.41, -2.33 | K37: -2.41, -0.69
A38: M-47 | B38: Edificación | C38: Muro block 0.15 que no carga | E38: 0.15 | F38: 1.424 | G38: =IF(Parámetros!$B$5="","",Parámetros!$B$5) | H38: =IF(G38="","",F38*G38) | J38: -23.84, -9.46 | K38: -23.50, -8.08
A39: M-48 | B39: Edificación | C39: Muro block 0.15 que no carga | D39: M1 | E39: 0.15 | F39: 1.391 | G39: =IF(Parámetros!$B$5="","",Parámetros!$B$5) | H39: =IF(G39="","",F39*G39) | J39: -10.71, -4.05 | K39: -10.71, -2.66
A40: M-49 | B40: Edificación | C40: Muro block 0.15 que no carga | D40: M5 | E40: 0.15 | F40: 1.378 | G40: =IF(Parámetros!$B$5="","",Parámetros!$B$5) | H40: =IF(G40="","",F40*G40) | J40: -4.15, 7.81 | K40: -2.77, 7.81
...

Sheet Vanos
A1: VANOS – DEDUCCIÓN
A2: Proyecto: Casa JPS – Sótano | Planos S-1 (DXF), S-7 y S-8 (PDF) | Rev. 1 – 2026-10-12 | Unidades: m, m²
A4: ID | B4: Muro | C4: Tipo de muro | D4: Ancho | E4: Alto | F4: Área a deducir | G4: Centro X,Y | H4: Observaciones
A5: V-01 | B5: M-24 | C5: Muro block 0.15 que carga | D5: 0.7 | E5: =IF(Parámetros!$B$7="","",Parámetros!$B$7) | F5: =IF(E5="","",D5*E5) | G5: -3.82, -0.59 | H5: Hueco colineal entre M-24 y M-34; muro trazado a altura total sobre el vano
A6: V-02 | B6: M-27 | C6: Muro block 0.15 que carga | D6: 0.9 | E6: =IF(Parámetros!$B$7="","",Parámetros!$B$7) | F6: =IF(E6="","",D6*E6) | G6: -3.89, 1.16 | H6: Hueco colineal entre M-27 y M-33; muro trazado a altura total sobre el vano
A7: V-03 | B7: M-30 | C7: Muro block 0.15 que carga | D7: 0.9 | E7: =IF(Parámetros!$B$7="","",Parámetros!$B$7) | F7: =IF(E7="","",D7*E7) | G7: -8.76, 1.16 | H7: Hueco colineal entre M-30 y M-38; muro trazado a altura total sobre el vano
A8: V-04 | B8: M-37 | C8: Muro block 0.15 que carga | D8: 0.6 | E8: =IF(Parámetros!$B$7="","",Parámetros!$B$7) | F8: =IF(E8="","",D8*E8) | G8: -2.69, -2.66 | H8: Hueco colineal entre M-37 y M-32; muro trazado a altura total sobre el vano
A9: V-05 | B9: M-52 | C9: Muro block 0.15 que no carga | D9: 0.652 | E9: =IF(Parámetros!$B$7="","",Parámetros!$B$7) | F9: =IF(E9="","",D9*E9) | G9: -2.41, -2.66 | H9: Hueco colineal entre M-52 y M-46; muro trazado a altura total sobre el vano
A10: TOTAL | D10: =SUM(D5:D9) | F10: =IF(COUNT(F5:F9)<COUNTA(A5:A9),"pendiente",SUM(F5:F9))

Sheet Pendientes
A1: PENDIENTES, RFI Y SUPUESTOS
A2: Proyecto: Casa JPS – Sótano | Planos S-1 (DXF), S-7 y S-8 (PDF) | Rev. 1 – 2026-10-12 | Unidades: m, m²
A4: No. | B4: Tipo | C4: Descripción | D4: Impacto
A5: 1 | B5: Resuelto | C5: Alturas tomadas de los cortes S-7 (A, B) y S-8 (C, D): corona de cimiento −4.65 a NPT −0.35 = 4.30 m, igual para muros de edificación y MC1.
A6: 2 | B6: RFI | C6: En S-7 Secc. A la losa sube a NPT 0.00 entre ejes 6 y 5; los muros bajo esa zona miden 4.65 m. Sin el xref de ejes no se puede ubicar en planta. | D6: +0.35 m en los muros de esa zona
A7: 3 | B7: Supuesto | C7: Altura de vanos 2.10 m solo para la deducción; el muro se cuantifica a altura total también sobre el vano (regla de cuantificación). | D7: Ajustar con plano arquitectónico
A8: 4 | B8: Dato faltante | C8: Tipos de muro M1–M35 (etiquetas del plano) se definen en Xref_Muros_Sotano, no incluido. Se clasificó por capa y leyenda: rojo = carga, gris = no carga; doble hilada sobre MC1 = muro de contención. | D8: Especificación de block y refuerzo
A9: 5 | B9: Supuesto | C9: Vanos detectados como huecos colineales de 0.55–2.50 m en muros de edificación (5 vanos). Puede haber vanos junto a esquinas no detectables sin plano arquitectónico. | D9: Deducción de vanos
A10: 6 | B10: Supuesto | C10: Huecos 0.10–0.85 m entre tramos = columnas o mochetas (no muro): MC-07→MC-13 0.60, MC-09→MC-16 0.50, M-56→M-58 0.50, MC-10→MC-09 0.20, MC-11→MC-10 0.60, MC-14→MC-06 0.50, M-59→M-56 0.22, MC-17→MC-18 0.60, MC-18→MC-14 0.30, M-33→M-26 0.15, MC-20→MC-07 0.80, M-35→M-29 0.30, M-39→M-28 0.15, M-41→M-49 0.36, M-42→M-41 0.36, M-49→M-40 0.36 | D10: Se cuantifican en columnas/mochetas
A11: 7 | B11: RFI | C11: M-40, M-41, M-42 y M-49 (block que no carga, y = 7.81) corren paralelos al muro MC1 a 0.88 m, sobre su cimiento. Confirmar si forman parte del sistema MC1 (cámara) o son muros de edificación. | D11: 11.63 ml
A12: 8 | B12: RFI | C12: Remates de doble hilada al NE, fuera de Z1-d y Z1-e (MC-16, MC-21, MC-22, MC-23), se incluyeron como muro MC1. | D12: 3.14 ml
A13: 9 | B13: Verificación | C13: Longitud por eje vs. conteo de unidades (n × 0.40): MC1 −2.3 %, 0.15 carga −5.3 %, 0.20 carga −4.3 %, 0.15 no carga −10.4 %. Las unidades se dibujaron traslapadas (paso real 0.36–0.39 m); manda la longitud por eje.
A14: 10 | B14: Limitación | C14: Los muros se entregan como bloques con atributos (doble clic) por tramo; no es el bloque dinámico de muro de proyectos anteriores (no está disponible aquí). Sustituir en AutoCAD si se requiere.
