Workbook

Sheet RESUMEN
A1: CASA JPS - RESUMEN DE MUROS (version Claude, desde emplantillados S-1, S-3, S-5)
A3: Nivel | B3: Tipo | C3: No. tramos | D3: Long. bruta (ml) | E3: Long. vanos (ml) | F3: Long. sin vanos (ml) | G3: Area neta (m2) | H3: V2 Claude long. (ml) | I3: V2 Claude area neta (m2) | J3: A mano long. (ml) | K3: A mano area neta (m2) | L3: Nota
A4: SÓTANO | B4: Muro de 10cm | C4: =COUNTIFS(MUROS!$A$4:$A$163,$A4,MUROS!$C$4:$C$163,$B4) | D4: =SUMIFS(MUROS!$I$4:$I$163,MUROS!$A$4:$A$163,$A4,MUROS!$C$4:$C$163,$B4) | E4: =SUMIFS(MUROS!$K$4:$K$163,MUROS!$A$4:$A$163,$A4,MUROS!$C$4:$C$163,$B4) | F4: =D4-E4 | G4: =SUMIFS(MUROS!$Q$4:$Q$163,MUROS!$A$4:$A$163,$A4,MUROS!$C$4:$C$163,$B4) | H4: 6.87 | I4: 32.71 | J4: 9.8 | K4: 44.05
A5: SÓTANO | B5: Muro de 15cm | C5: =COUNTIFS(MUROS!$A$4:$A$163,$A5,MUROS!$C$4:$C$163,$B5) | D5: =SUMIFS(MUROS!$I$4:$I$163,MUROS!$A$4:$A$163,$A5,MUROS!$C$4:$C$163,$B5) | E5: =SUMIFS(MUROS!$K$4:$K$163,MUROS!$A$4:$A$163,$A5,MUROS!$C$4:$C$163,$B5) | F5: =D5-E5 | G5: =SUMIFS(MUROS!$Q$4:$Q$163,MUROS!$A$4:$A$163,$A5,MUROS!$C$4:$C$163,$B5) | H5: 51.49 | I5: 232.87 | J5: 58.45 | K5: 276.69
A6: SÓTANO | B6: Muro de 20cm | C6: =COUNTIFS(MUROS!$A$4:$A$163,$A6,MUROS!$C$4:$C$163,$B6) | D6: =SUMIFS(MUROS!$I$4:$I$163,MUROS!$A$4:$A$163,$A6,MUROS!$C$4:$C$163,$B6) | E6: =SUMIFS(MUROS!$K$4:$K$163,MUROS!$A$4:$A$163,$A6,MUROS!$C$4:$C$163,$B6) | F6: =D6-E6 | G6: =SUMIFS(MUROS!$Q$4:$Q$163,MUROS!$A$4:$A$163,$A6,MUROS!$C$4:$C$163,$B6) | H6: 20.5 | I6: 96.27 | J6: 16.57 | K6: 75.86
A7: SÓTANO | B7: Muro de contención de 30cm | C7: =COUNTIFS(MUROS!$A$4:$A$163,$A7,MUROS!$C$4:$C$163,$B7) | D7: =SUMIFS(MUROS!$I$4:$I$163,MUROS!$A$4:$A$163,$A7,MUROS!$C$4:$C$163,$B7) | E7: =SUMIFS(MUROS!$K$4:$K$163,MUROS!$A$4:$A$163,$A7,MUROS!$C$4:$C$163,$B7) | F7: =D7-E7 | G7: =SUMIFS(MUROS!$Q$4:$Q$163,MUROS!$A$4:$A$163,$A7,MUROS!$C$4:$C$163,$B7) | H7: 114.83 | I7: 493.75 | J7: 126.26 | K7: 545.18 | L7: A mano: contencion = 0.20 + 0.30 (1.83 + 124.43 ml)
A8: SÓTANO | B8: Subtotal | C8: =SUM(C4:C7) | D8: =SUM(D4:D7) | E8: =SUM(E4:E7) | F8: =SUM(F4:F7) | G8: =SUM(G4:G7) | H8: =SUM(H4:H7) | I8: =SUM(I4:I7) | J8: =SUM(J4:J7) | K8: =SUM(K4:K7)
A10: NIVEL 1 | B10: Muro de 10cm | C10: =COUNTIFS(MUROS!$A$4:$A$163,$A10,MUROS!$C$4:$C$163,$B10) | D10: =SUMIFS(MUROS!$I$4:$I$163,MUROS!$A$4:$A$163,$A10,MUROS!$C$4:$C$163,$B10) | E10: =SUMIFS(MUROS!$K$4:$K$163,MUROS!$A$4:$A$163,$A10,MUROS!$C$4:$C$163,$B10) | F10: =D10-E10 | G10: =SUMIFS(MUROS!$Q$4:$Q$163,MUROS!$A$4:$A$163,$A10,MUROS!$C$4:$C$163,$B10) | H10: 8.23 | I10: 26.33 | J10: 6.92 | K10: 22.15
A11: NIVEL 1 | B11: Muro de 15cm | C11: =COUNTIFS(MUROS!$A$4:$A$163,$A11,MUROS!$C$4:$C$163,$B11) | D11: =SUMIFS(MUROS!$I$4:$I$163,MUROS!$A$4:$A$163,$A11,MUROS!$C$4:$C$163,$B11) | E11: =SUMIFS(MUROS!$K$4:$K$163,MUROS!$A$4:$A$163,$A11,MUROS!$C$4:$C$163,$B11) | F11: =D11-E11 | G11: =SUMIFS(MUROS!$Q$4:$Q$163,MUROS!$A$4:$A$163,$A11,MUROS!$C$4:$C$163,$B11) | H11: 77.72 | I11: 275.9 | J11: 95.76 | K11: 373.27
A12: NIVEL 1 | B12: Muro perimetral de 15cm | C12: =COUNTIFS(MUROS!$A$4:$A$163,$A12,MUROS!$C$4:$C$163,$B12) | D12: =SUMIFS(MUROS!$I$4:$I$163,MUROS!$A$4:$A$163,$A12,MUROS!$C$4:$C$163,$B12) | E12: =SUMIFS(MUROS!$K$4:$K$163,MUROS!$A$4:$A$163,$A12,MUROS!$C$4:$C$163,$B12) | F12: =D12-E12 | G12: =SUMIFS(MUROS!$Q$4:$Q$163,MUROS!$A$4:$A$163,$A12,MUROS!$C$4:$C$163,$B12) | H12: 69 | I12: 244.94 | J12: 69.06 | K12: 245.18
A13: NIVEL 1 | B13: Muro de 20cm | C13: =COUNTIFS(MUROS!$A$4:$A$163,$A13,MUROS!$C$4:$C$163,$B13) | D13: =SUMIFS(MUROS!$I$4:$I$163,MUROS!$A$4:$A$163,$A13,MUROS!$C$4:$C$163,$B13) | E13: =SUMIFS(MUROS!$K$4:$K$163,MUROS!$A$4:$A$163,$A13,MUROS!$C$4:$C$163,$B13) | F13: =D13-E13 | G13: =SUMIFS(MUROS!$Q$4:$Q$163,MUROS!$A$4:$A$163,$A13,MUROS!$C$4:$C$163,$B13) | H13: 40.82 | I13: 144.93 | J13: 38.59 | K13: 135.45
A14: NIVEL 1 | B14: Muro de contención de 30cm | C14: =COUNTIFS(MUROS!$A$4:$A$163,$A14,MUROS!$C$4:$C$163,$B14) | D14: =SUMIFS(MUROS!$I$4:$I$163,MUROS!$A$4:$A$163,$A14,MUROS!$C$4:$C$163,$B14) | E14: =SUMIFS(MUROS!$K$4:$K$163,MUROS!$A$4:$A$163,$A14,MUROS!$C$4:$C$163,$B14) | F14: =D14-E14 | G14: =SUMIFS(MUROS!$Q$4:$Q$163,MUROS!$A$4:$A$163,$A14,MUROS!$C$4:$C$163,$B14) | H14: 3.42 | I14: 12.16 | J14: 7.91 | K14: 28.08
A15: NIVEL 1 | B15: Subtotal | C15: =SUM(C10:C14) | D15: =SUM(D10:D14) | E15: =SUM(E10:E14) | F15: =SUM(F10:F14) | G15: =SUM(G10:G14) | H15: =SUM(H10:H14) | I15: =SUM(I10:I14) | J15: =SUM(J10:J14) | K15: =SUM(K10:K14)
A17: NIVEL 2 | B17: Muro de 10cm | C17: =COUNTIFS(MUROS!$A$4:$A$163,$A17,MUROS!$C$4:$C$163,$B17) | D17: =SUMIFS(MUROS!$I$4:$I$163,MUROS!$A$4:$A$163,$A17,MUROS!$C$4:$C$163,$B17) | E17: =SUMIFS(MUROS!$K$4:$K$163,MUROS!$A$4:$A$163,$A17,MUROS!$C$4:$C$163,$B17) | F17: =D17-E17 | G17: =SUMIFS(MUROS!$Q$4:$Q$163,MUROS!$A$4:$A$163,$A17,MUROS!$C$4:$C$163,$B17) | H17: 14.23 | I17: 45.55 | J17: 13.45 | K17: 44.79
A18: NIVEL 2 | B18: Muro de 15cm | C18: =COUNTIFS(MUROS!$A$4:$A$163,$A18,MUROS!$C$4:$C$163,$B18) | D18: =SUMIFS(MUROS!$I$4:$I$163,MUROS!$A$4:$A$163,$A18,MUROS!$C$4:$C$163,$B18) | E18: =SUMIFS(MUROS!$K$4:$K$163,MUROS!$A$4:$A$163,$A18,MUROS!$C$4:$C$163,$B18) | F18: =D18-E18 | G18: =SUMIFS(MUROS!$Q$4:$Q$163,MUROS!$A$4:$A$163,$A18,MUROS!$C$4:$C$163,$B18) | H18: 157.73 | I18: 522.64 | J18: 161.67 | K18: 540.74
A19: NIVEL 2 | B19: Muro de 20cm | C19: =COUNTIFS(MUROS!$A$4:$A$163,$A19,MUROS!$C$4:$C$163,$B19) | D19: =SUMIFS(MUROS!$I$4:$I$163,MUROS!$A$4:$A$163,$A19,MUROS!$C$4:$C$163,$B19) | E19: =SUMIFS(MUROS!$K$4:$K$163,MUROS!$A$4:$A$163,$A19,MUROS!$C$4:$C$163,$B19) | F19: =D19-E19 | G19: =SUMIFS(MUROS!$Q$4:$Q$163,MUROS!$A$4:$A$163,$A19,MUROS!$C$4:$C$163,$B19) | H19: 17.39 | I19: 57.87 | J19: 9.77 | K19: 32.63
A20: NIVEL 2 | B20: Muro de contención de 30cm | C20: =COUNTIFS(MUROS!$A$4:$A$163,$A20,MUROS!$C$4:$C$163,$B20) | D20: =SUMIFS(MUROS!$I$4:$I$163,MUROS!$A$4:$A$163,$A20,MUROS!$C$4:$C$163,$B20) | E20: =SUMIFS(MUROS!$K$4:$K$163,MUROS!$A$4:$A$163,$A20,MUROS!$C$4:$C$163,$B20) | F20: =D20-E20 | G20: =SUMIFS(MUROS!$Q$4:$Q$163,MUROS!$A$4:$A$163,$A20,MUROS!$C$4:$C$163,$B20) | H20: 4.15 | I20: 13.28 | J20: 7.73 | K20: 28.15
A21: NIVEL 2 | B21: Subtotal | C21: =SUM(C17:C20) | D21: =SUM(D17:D20) | E21: =SUM(E17:E20) | F21: =SUM(F17:F20) | G21: =SUM(G17:G20) | H21: =SUM(H17:H20) | I21: =SUM(I17:I20) | J21: =SUM(J17:J20) | K21: =SUM(K17:K20)

Sheet PARAMETROS
A1: CASA JPS - MUROS - PARAMETROS
A3: Parametro | B3: Valor | C3: Unidad | D3: Etiqueta | E3: Fuente
A4: SÓTANO|General | B4: 4.3 | C4: m | D4: [Dato verificado] | E4: S-1 detalle MC1: 0.80 bajo NPT -3.85 + 3.50 hasta losa NPT -0.35; detalle CC1: 0.80
A5: SÓTANO|Bajo losa NPT 0.00 (ejes 5-6, A-C) | B5: 4.65 | C5: m | D5: [Cálculo] | E5: 0.80 + 3.85 (NPT -3.85 a losa NPT 0.00, S-2 simbologia y DL3); no aplica a contencion (detalle MC1 = 4.30)
A6: NIVEL 1|General | B6: 3.55 | C6: m | D6: [Cálculo] | E6: S-7/S-8: piso NPT -0.35 a losa NPT +3.20
A7: NIVEL 1|Piso NPT 0.00 (ejes 5-6, A-C) | B7: 3.2 | C7: m | D7: [Cálculo] | E7: S-2: piso NPT 0.00 entre ejes 5-6 y A-C a losa +3.20
A8: NIVEL 1|Ala este (losa +4.20) | B8: 4.55 | C8: m | D8: [Cálculo] | E8: S-7 seccion A: ala al este del eje 6, piso NPT -0.35 a losa NPT +4.20
A9: NIVEL 2|General | B9: 3.2 | C9: m | D9: [Cálculo] | E9: S-7/S-8: NPT +3.20 a NPT +6.40
A10: Altura de puerta (vano) | B10: 2.1 | C10: m | D10: [Supuesto] | E10: No esta en planos estructurales; criterio del libro

Sheet MUROS
A1: MUROS POR TRAMO - medidos del emplantillado (blocks) de cada planta
A3: Nivel | B3: ID | C3: Tipo | D3: Espesor (m) | E3: X inicio | F3: Y inicio | G3: X fin | H3: Y fin | I3: Longitud bruta (ml) | J3: No. vanos puerta | K3: Long. vanos (ml) | L3: Long. muro sin vanos (ml) | M3: Zona | N3: Altura muro (m) | O3: Area bruta (m2) | P3: Area vanos (m2) | Q3: Area neta (m2) | R3: Plano | S3: Metodo | T3: Observaciones
A4: SÓTANO | B4: SOT-01 | C4: Muro de 10cm | D4: 0.1 | E4: -10.663 | F4: -2.614 | G4: -9.961 | H4: -2.614 | I4: 0.702 | J4: 0 | K4: 0 | L4: =I4-K4 | M4: General | N4: =VLOOKUP(A4&"|"&M4,PARAMETROS!$A$4:$B$9,2,FALSE) | O4: =I4*N4 | P4: =K4*PARAMETROS!$B$10 | Q4: =O4-P4 | R4: S-1 CIMENTACION Y DETALLES | S4: Corrida de blocks colineales; union por columna/mocheta; esquina al muro mas largo
A5: SÓTANO | B5: SOT-02 | C5: Muro de 15cm | D5: 0.15 | E5: -10.553 | F5: -0.589 | G5: -2.612 | H5: -0.589 | I5: 7.941 | J5: 1 | K5: 0.7 | L5: =I5-K5 | M5: General | N5: =VLOOKUP(A5&"|"&M5,PARAMETROS!$A$4:$B$9,2,FALSE) | O5: =I5*N5 | P5: =K5*PARAMETROS!$B$10 | Q5: =O5-P5 | R5: S-1 CIMENTACION Y DETALLES | S5: Corrida de blocks colineales; union por columna/mocheta; esquina al muro mas largo
A6: SÓTANO | B6: SOT-03 | C6: Muro de 15cm | D6: 0.15 | E6: -11.511 | F6: 1.158 | G6: -2.6 | H6: 1.158 | I6: 8.911 | J6: 2 | K6: 1.8 | L6: =I6-K6 | M6: General | N6: =VLOOKUP(A6&"|"&M6,PARAMETROS!$A$4:$B$9,2,FALSE) | O6: =I6*N6 | P6: =K6*PARAMETROS!$B$10 | Q6: =O6-P6 | R6: S-1 CIMENTACION Y DETALLES | S6: Corrida de blocks colineales; union por columna/mocheta; esquina al muro mas largo
A7: SÓTANO | B7: SOT-04 | C7: Muro de 15cm | D7: 0.15 | E7: -2.6 | F7: 1.158 | G7: 1.81 | H7: 1.158 | I7: 4.41 | J7: 0 | K7: 0 | L7: =I7-K7 | M7: General | N7: =VLOOKUP(A7&"|"&M7,PARAMETROS!$A$4:$B$9,2,FALSE) | O7: =I7*N7 | P7: =K7*PARAMETROS!$B$10 | Q7: =O7-P7 | R7: S-1 CIMENTACION Y DETALLES | S7: Corrida de blocks colineales; union por columna/mocheta; esquina al muro mas largo
A8: SÓTANO | B8: SOT-05 | C8: Muro de 15cm | D8: 0.15 | E8: 1.81 | F8: 1.158 | G8: 1.889 | H8: 1.158 | I8: 0.079 | J8: 0 | K8: 0 | L8: =I8-K8 | M8: General | N8: =VLOOKUP(A8&"|"&M8,PARAMETROS!$A$4:$B$9,2,FALSE) | O8: =I8*N8 | P8: =K8*PARAMETROS!$B$10 | Q8: =O8-P8 | R8: S-1 CIMENTACION Y DETALLES | S8: Corrida de blocks colineales; union por columna/mocheta; esquina al muro mas largo | T8: Tramo corto: verificar
A9: SÓTANO | B9: SOT-06 | C9: Muro de 15cm | D9: 0.15 | E9: -15.261 | F9: 5.864 | G9: -11.511 | H9: 5.864 | I9: 3.75 | J9: 0 | K9: 0 | L9: =I9-K9 | M9: General | N9: =VLOOKUP(A9&"|"&M9,PARAMETROS!$A$4:$B$9,2,FALSE) | O9: =I9*N9 | P9: =K9*PARAMETROS!$B$10 | Q9: =O9-P9 | R9: S-1 CIMENTACION Y DETALLES | S9: Corrida de blocks colineales; union por columna/mocheta; esquina al muro mas largo
A10: SÓTANO | B10: SOT-07 | C10: Muro de 15cm | D10: 0.15 | E10: -11.511 | F10: 7.81 | G10: -2.6 | H10: 7.81 | I10: 8.911 | J10: 0 | K10: 0 | L10: =I10-K10 | M10: General | N10: =VLOOKUP(A10&"|"&M10,PARAMETROS!$A$4:$B$9,2,FALSE) | O10: =I10*N10 | P10: =K10*PARAMETROS!$B$10 | Q10: =O10-P10 | R10: S-1 CIMENTACION Y DETALLES | S10: Corrida de blocks colineales; union por columna/mocheta; esquina al muro mas largo | T10: 3 hueco(s) de columna/mocheta incluidos en la longitud
A11: SÓTANO | B11: SOT-08 | C11: Muro de 15cm | D11: 0.15 | E11: -2.6 | F11: 7.81 | G11: 1.81 | H11: 7.81 | I11: 4.41 | J11: 0 | K11: 0 | L11: =I11-K11 | M11: Bajo losa NPT 0.00 (ejes 5-6, A-C) | N11: =VLOOKUP(A11&"|"&M11,PARAMETROS!$A$4:$B$9,2,FALSE) | O11: =I11*N11 | P11: =K11*PARAMETROS!$B$10 | Q11: =O11-P11 | R11: S-1 CIMENTACION Y DETALLES | S11: Corrida de blocks colineales; union por columna/mocheta; esquina al muro mas largo | T11: 3 hueco(s) de columna/mocheta incluidos en la longitud
A12: SÓTANO | B12: SOT-09 | C12: Muro de 15cm | D12: 0.15 | E12: 1.81 | F12: 7.81 | G12: 1.889 | H12: 7.81 | I12: 0.079 | J12: 0 | K12: 0 | L12: =I12-K12 | M12: Bajo losa NPT 0.00 (ejes 5-6, A-C) | N12: =VLOOKUP(A12&"|"&M12,PARAMETROS!$A$4:$B$9,2,FALSE) | O12: =I12*N12 | P12: =K12*PARAMETROS!$B$10 | Q12: =O12-P12 | R12: S-1 CIMENTACION Y DETALLES | S12: Corrida de blocks colineales; union por columna/mocheta; esquina al muro mas largo | T12: Tramo corto: verificar; 3 hueco(s) de columna/mocheta incluidos en la longitud
A13: SÓTANO | B13: SOT-10 | C13: Muro de 15cm | D13: 0.15 | E13: 1.579 | F13: 8.76 | G13: 1.81 | H13: 8.76 | I13: 0.231 | J13: 0 | K13: 0 | L13: =I13-K13 | M13: Bajo losa NPT 0.00 (ejes 5-6, A-C) | N13: =VLOOKUP(A13&"|"&M13,PARAMETROS!$A$4:$B$9,2,FALSE) | O13: =I13*N13 | P13: =K13*PARAMETROS!$B$10 | Q13: =O13-P13 | R13: S-1 CIMENTACION Y DETALLES | S13: Corrida de blocks colineales; union por columna/mocheta; esquina al muro mas largo | T13: Tramo corto: verificar
A14: SÓTANO | B14: SOT-11 | C14: Muro de 15cm | D14: 0.15 | E14: 1.81 | F14: 8.76 | G14: 1.889 | H14: 8.76 | I14: 0.079 | J14: 0 | K14: 0 | L14: =I14-K14 | M14: Bajo losa NPT 0.00 (ejes 5-6, A-C) | N14: =VLOOKUP(A14&"|"&M14,PARAMETROS!$A$4:$B$9,2,FALSE) | O14: =I14*N14 | P14: =K14*PARAMETROS!$B$10 | Q14: =O14-P14 | R14: S-1 CIMENTACION Y DETALLES | S14: Corrida de blocks colineales; union por columna/mocheta; esquina al muro mas largo | T14: Tramo corto: verificar
A15: SÓTANO | B15: SOT-12 | C15: Muro de contención de 30cm | D15: 0.3 | E15: -10.663 | F15: -3.614 | G15: -2.6 | H15: -3.614 | I15: 8.063 | J15: 0 | K15: 0 | L15: =I15-K15 | M15: General | N15: =VLOOKUP(A15&"|"&M15,PARAMETROS!$A$4:$B$9,2,FALSE) | O15: =I15*N15 | P15: =K15*PARAMETROS!$B$10 | Q15: =O15-P15 | R15: S-1 CIMENTACION Y DETALLES | S15: Corrida de blocks colineales; union por columna/mocheta; esquina al muro mas largo
A16: SÓTANO | B16: SOT-13 | C16: Muro de contención de 30cm | D16: 0.3 | E16: -2.6 | F16: -3.614 | G16: 1.589 | H16: -3.614 | I16: 4.189 | J16: 0 | K16: 0 | L16: =I16-K16 | M16: General | N16: =VLOOKUP(A16&"|"&M16,PARAMETROS!$A$4:$B$9,2,FALSE) | O16: =I16*N16 | P16: =K16*PARAMETROS!$B$10 | Q16: =O16-P16 | R16: S-1 CIMENTACION Y DETALLES | S16: Corrida de blocks colineales; union por columna/mocheta; esquina al muro mas largo
A17: SÓTANO | B17: SOT-14 | C17: Muro de contención de 30cm | D17: 0.3 | E17: -18.955 | F17: 7.886 | G17: -11.361 | H17: 7.886 | I17: 7.594 | J17: 0 | K17: 0 | L17: =I17-K17 | M17: General | N17: =VLOOKUP(A17&"|"&M17,PARAMETROS!$A$4:$B$9,2,FALSE) | O17: =I17*N17 | P17: =K17*PARAMETROS!$B$10 | Q17: =O17-P17 | R17: S-1 CIMENTACION Y DETALLES | S17: Corrida de blocks colineales; union por columna/mocheta; esquina al muro mas largo
A18: SÓTANO | B18: SOT-15 | C18: Muro de contención de 30cm | D18: 0.3 | E18: -11.611 | F18: 8.685 | G18: -2.6 | H18: 8.685 | I18: 9.011 | J18: 0 | K18: 0 | L18: =I18-K18 | M18: General | N18: =VLOOKUP(A18&"|"&M18,PARAMETROS!$A$4:$B$9,2,FALSE) | O18: =I18*N18 | P18: =K18*PARAMETROS!$B$10 | Q18: =O18-P18 | R18: S-1 CIMENTACION Y DETALLES | S18: Corrida de blocks colineales; union por columna/mocheta; esquina al muro mas largo
A19: SÓTANO | B19: SOT-16 | C19: Muro de contención de 30cm | D19: 0.3 | E19: -2.6 | F19: 8.685 | G19: 1.81 | H19: 8.685 | I19: 4.41 | J19: 0 | K19: 0 | L19: =I19-K19 | M19: General | N19: =VLOOKUP(A19&"|"&M19,PARAMETROS!$A$4:$B$9,2,FALSE) | O19: =I19*N19 | P19: =K19*PARAMETROS!$B$10 | Q19: =O19-P19 | R19: S-1 CIMENTACION Y DETALLES | S19: Corrida de blocks colineales; union por columna/mocheta; esquina al muro mas largo
A20: SÓTANO | B20: SOT-17 | C20: Muro de contención de 30cm | D20: 0.3 | E20: 1.81 | F20: 8.685 | G20: 1.889 | H20: 8.685 | I20: 0.079 | J20: 0 | K20: 0 | L20: =I20-K20 | M20: General | N20: =VLOOKUP(A20&"|"&M20,PARAMETROS!$A$4:$B$9,2,FALSE) | O20: =I20*N20 | P20: =K20*PARAMETROS!$B$10 | Q20: =O20-P20 | R20: S-1 CIMENTACION Y DETALLES | S20: Corrida de blocks colineales; union por columna/mocheta; esquina al muro mas largo | T20: Tramo corto: verificar
A21: SÓTANO | B21: SOT-18 | C21: Muro de 15cm | D21: 0.15 | E21: -12.56 | F21: -7.342 | G21: -12.226 | H21: -6.838 | I21: 0.604 | J21: 0 | K21: 0 | L21: =I21-K21 | M21: General | N21: =VLOOKUP(A21&"|"&M21,PARAMETROS!$A$4:$B$9,2,FALSE) | O21: =I21*N21 | P21: =K21*PARAMETROS!$B$10 | Q21: =O21-P21 | R21: S-1 CIMENTACION Y DETALLES | S21: Corrida de blocks colineales; union por columna/mocheta; esquina al muro mas largo
A22: SÓTANO | B22: SOT-19 | C22: Muro de contención de 30cm | D22: 0.3 | E22: -17.703 | F22: -14.949 | G22: -10.639 | H22: -4.316 | I22: 12.765 | J22: 0 | K22: 0 | L22: =I22-K22 | M22: General | N22: =VLOOKUP(A22&"|"&M22,PARAMETROS!$A$4:$B$9,2,FALSE) | O22: =I22*N22 | P22: =K22*PARAMETROS!$B$10 | Q22: =O22-P22 | R22: S-1 CIMENTACION Y DETALLES | S22: Corrida de blocks colineales; union por columna/mocheta; esquina al muro mas largo | T22: 3 hueco(s) de columna/mocheta incluidos en la longitud
A23: SÓTANO | B23: SOT-20 | C23: Muro de contención de 30cm | D23: 0.3 | E23: -29.887 | F23: -8.298 | G23: -19.035 | H23: 8.036 | I23: 19.61 | J23: 0 | K23: 0 | L23: =I23-K23 | M23: General | N23: =VLOOKUP(A23&"|"&M23,PARAMETROS!$A$4:$B$9,2,FALSE) | O23: =I23*N23 | P23: =K23*PARAMETROS!$B$10 | Q23: =O23-P23 | R23: S-1 CIMENTACION Y DETALLES | S23: Corrida de blocks colineales; union por columna/mocheta; esquina al muro mas largo
A24: SÓTANO | B24: SOT-21 | C24: Muro de 15cm | D24: 0.15 | E24: 8.524 | F24: -3.4 | G24: 8.601 | H24: -3.215 | I24: 0.2 | J24: 0 | K24: 0 | L24: =I24-K24 | M24: General | N24: =VLOOKUP(A24&"|"&M24,PARAMETROS!$A$4:$B$9,2,FALSE) | O24: =I24*N24 | P24: =K24*PARAMETROS!$B$10 | Q24: =O24-P24 | R24: S-1 CIMENTACION Y DETALLES | S24: Corrida de blocks colineales; union por columna/mocheta; esquina al muro mas largo | T24: Tramo corto: verificar
A25: SÓTANO | B25: SOT-22 | C25: Muro de 20cm | D25: 0.2 | E25: 3.526 | F25: 1.308 | G25: 6.266 | H25: 7.878 | I25: 7.118 | J25: 0 | K25: 0 | L25: =I25-K25 | M25: General | N25: =VLOOKUP(A25&"|"&M25,PARAMETROS!$A$4:$B$9,2,FALSE) | O25: =I25*N25 | P25: =K25*PARAMETROS!$B$10 | Q25: =O25-P25 | R25: S-1 CIMENTACION Y DETALLES | S25: Corrida de blocks colineales; union por columna/mocheta; esquina al muro mas largo | T25: 2 hueco(s) de columna/mocheta incluidos en la longitud
A26: SÓTANO | B26: SOT-23 | C26: Muro de contención de 30cm | D26: 0.3 | E26: 7.4 | F26: -5.9 | G26: 12.127 | H26: 5.434 | I26: 12.28 | J26: 0 | K26: 0 | L26: =I26-K26 | M26: General | N26: =VLOOKUP(A26&"|"&M26,PARAMETROS!$A$4:$B$9,2,FALSE) | O26: =I26*N26 | P26: =K26*PARAMETROS!$B$10 | Q26: =O26-P26 | R26: S-1 CIMENTACION Y DETALLES | S26: Corrida de blocks colineales; union por columna/mocheta; esquina al muro mas largo | T26: 3 hueco(s) de columna/mocheta incluidos en la longitud
A27: SÓTANO | B27: SOT-24 | C27: Muro de 15cm | D27: 0.15 | E27: -23.849 | F27: -9.485 | G27: -23.501 | H27: -8.077 | I27: 1.45 | J27: 0 | K27: 0 | L27: =I27-K27 | M27: General | N27: =VLOOKUP(A27&"|"&M27,PARAMETROS!$A$4:$B$9,2,FALSE) | O27: =I27*N27 | P27: =K27*PARAMETROS!$B$10 | Q27: =O27-P27 | R27: S-1 CIMENTACION Y DETALLES | S27: Corrida de blocks colineales; union por columna/mocheta; esquina al muro mas largo
A28: SÓTANO | B28: SOT-25 | C28: Muro de 15cm | D28: 0.15 | E28: -26.81 | F28: -8.751 | G28: -26.45 | H28: -7.3 | I28: 1.495 | J28: 0 | K28: 0 | L28: =I28-K28 | M28: General | N28: =VLOOKUP(A28&"|"&M28,PARAMETROS!$A$4:$B$9,2,FALSE) | O28: =I28*N28 | P28: =K28*PARAMETROS!$B$10 | Q28: =O28-P28 | R28: S-1 CIMENTACION Y DETALLES | S28: Corrida de blocks colineales; union por columna/mocheta; esquina al muro mas largo
A29: SÓTANO | B29: SOT-26 | C29: Muro de contención de 30cm | D29: 0.3 | E29: -18.041 | F29: -16.934 | G29: -17.463 | H29: -14.604 | I29: 2.4 | J29: 0 | K29: 0 | L29: =I29-K29 | M29: General | N29: =VLOOKUP(A29&"|"&M29,PARAMETROS!$A$4:$B$9,2,FALSE) | O29: =I29*N29 | P29: =K29*PARAMETROS!$B$10 | Q29: =O29-P29 | R29: S-1 CIMENTACION Y DETALLES | S29: Corrida de blocks colineales; union por columna/mocheta; esquina al muro mas largo
A30: SÓTANO | B30: SOT-27 | C30: Muro de 10cm | D30: 0.1 | E30: 1.539 | F30: -3.464 | G30: 1.539 | H30: -0.514 | I30: 2.95 | J30: 0 | K30: 0 | L30: =I30-K30 | M30: General | N30: =VLOOKUP(A30&"|"&M30,PARAMETROS!$A$4:$B$9,2,FALSE) | O30: =I30*N30 | P30: =K30*PARAMETROS!$B$10 | Q30: =O30-P30 | R30: S-1 CIMENTACION Y DETALLES | S30: Corrida de blocks colineales; union por columna/mocheta; esquina al muro mas largo
A31: SÓTANO | B31: SOT-28 | C31: Muro de 10cm | D31: 0.1 | E31: -2.407 | F31: -3.464 | G31: -2.407 | H31: -0.664 | I31: 2.8 | J31: 0 | K31: 0 | L31: =I31-K31 | M31: General | N31: =VLOOKUP(A31&"|"&M31,PARAMETROS!$A$4:$B$9,2,FALSE) | O31: =I31*N31 | P31: =K31*PARAMETROS!$B$10 | Q31: =O31-P31 | R31: S-1 CIMENTACION Y DETALLES | S31: Corrida de blocks colineales; union por columna/mocheta; esquina al muro mas largo | T31: 1 hueco(s) de columna/mocheta incluidos en la longitud
A32: SÓTANO | B32: SOT-29 | C32: Muro de 10cm | D32: 0.1 | E32: -9.108 | F32: -3.464 | G32: -9.108 | H32: -2.84 | I32: 0.624 | J32: 0 | K32: 0 | L32: =I32-K32 | M32: General | N32: =VLOOKUP(A32&"|"&M32,PARAMETROS!$A$4:$B$9,2,FALSE) | O32: =I32*N32 | P32: =K32*PARAMETROS!$B$10 | Q32: =O32-P32 | R32: S-1 CIMENTACION Y DETALLES | S32: Corrida de blocks colineales; union por columna/mocheta; esquina al muro mas largo
A33: SÓTANO | B33: SOT-30 | C33: Muro de 10cm | D33: 0.1 | E33: -10.713 | F33: -4.156 | G33: -10.713 | H33: -2.564 | I33: 1.593 | J33: 0 | K33: 0 | L33: =I33-K33 | M33: General | N33: =VLOOKUP(A33&"|"&M33,PARAMETROS!$A$4:$B$9,2,FALSE) | O33: =I33*N33 | P33: =K33*PARAMETROS!$B$10 | Q33: =O33-P33 | R33: S-1 CIMENTACION Y DETALLES | S33: Corrida de blocks colineales; union por columna/mocheta; esquina al muro mas largo
A34: SÓTANO | B34: SOT-31 | C34: Muro de 15cm | D34: 0.15 | E34: -2.687 | F34: -3.464 | G34: -2.687 | H34: -0.664 | I34: 2.8 | J34: 0 | K34: 0 | L34: =I34-K34 | M34: General | N34: =VLOOKUP(A34&"|"&M34,PARAMETROS!$A$4:$B$9,2,FALSE) | O34: =I34*N34 | P34: =K34*PARAMETROS!$B$10 | Q34: =O34-P34 | R34: S-1 CIMENTACION Y DETALLES | S34: Corrida de blocks colineales; union por columna/mocheta; esquina al muro mas largo | T34: 1 hueco(s) de columna/mocheta incluidos en la longitud
A35: SÓTANO | B35: SOT-32 | C35: Muro de 15cm | D35: 0.15 | E35: -5.038 | F35: -3.464 | G35: -5.038 | H35: -0.664 | I35: 2.8 | J35: 0 | K35: 0 | L35: =I35-K35 | M35: General | N35: =VLOOKUP(A35&"|"&M35,PARAMETROS!$A$4:$B$9,2,FALSE) | O35: =I35*N35 | P35: =K35*PARAMETROS!$B$10 | Q35: =O35-P35 | R35: S-1 CIMENTACION Y DETALLES | S35: Corrida de blocks colineales; union por columna/mocheta; esquina al muro mas largo
A36: SÓTANO | B36: SOT-33 | C36: Muro de 15cm | D36: 0.15 | E36: -10.688 | F36: 0.428 | G36: -10.688 | H36: 1.083 | I36: 0.655 | J36: 0 | K36: 0 | L36: =I36-K36 | M36: General | N36: =VLOOKUP(A36&"|"&M36,PARAMETROS!$A$4:$B$9,2,FALSE) | O36: =I36*N36 | P36: =K36*PARAMETROS!$B$10 | Q36: =O36-P36 | R36: S-1 CIMENTACION Y DETALLES | S36: Corrida de blocks colineales; union por columna/mocheta; esquina al muro mas largo
A37: SÓTANO | B37: SOT-34 | C37: Muro de 15cm | D37: 0.15 | E37: -11.436 | F37: 1.233 | G37: -11.436 | H37: 7.735 | I37: 6.502 | J37: 0 | K37: 0 | L37: =I37-K37 | M37: General | N37: =VLOOKUP(A37&"|"&M37,PARAMETROS!$A$4:$B$9,2,FALSE) | O37: =I37*N37 | P37: =K37*PARAMETROS!$B$10 | Q37: =O37-P37 | R37: S-1 CIMENTACION Y DETALLES | S37: Corrida de blocks colineales; union por columna/mocheta; esquina al muro mas largo
A38: SÓTANO | B38: SOT-35 | C38: Muro de 15cm | D38: 0.15 | E38: -16.426 | F38: 5.939 | G38: -16.426 | H38: 7.736 | I38: 1.797 | J38: 0 | K38: 0 | L38: =I38-K38 | M38: General | N38: =VLOOKUP(A38&"|"&M38,PARAMETROS!$A$4:$B$9,2,FALSE) | O38: =I38*N38 | P38: =K38*PARAMETROS!$B$10 | Q38: =O38-P38 | R38: S-1 CIMENTACION Y DETALLES | S38: Corrida de blocks colineales; union por columna/mocheta; esquina al muro mas largo
A39: SÓTANO | B39: SOT-36 | C39: Muro de 20cm | D39: 0.2 | E39: 1.989 | F39: -3.564 | G39: 1.989 | H39: 1.526 | I39: 5.09 | J39: 0 | K39: 0 | L39: =I39-K39 | M39: General | N39: =VLOOKUP(A39&"|"&M39,PARAMETROS!$A$4:$B$9,2,FALSE) | O39: =I39*N39 | P39: =K39*PARAMETROS!$B$10 | Q39: =O39-P39 | R39: S-1 CIMENTACION Y DETALLES | S39: Corrida de blocks colineales; union por columna/mocheta; esquina al muro mas largo
A40: SÓTANO | B40: SOT-37 | C40: Muro de 20cm | D40: 0.2 | E40: 1.789 | F40: 1.233 | G40: 1.789 | H40: 7.522 | I40: 6.289 | J40: 0 | K40: 0 | L40: =I40-K40 | M40: Bajo losa NPT 0.00 (ejes 5-6, A-C) | N40: =VLOOKUP(A40&"|"&M40,PARAMETROS!$A$4:$B$9,2,FALSE) | O40: =I40*N40 | P40: =K40*PARAMETROS!$B$10 | Q40: =O40-P40 | R40: S-1 CIMENTACION Y DETALLES | S40: Corrida de blocks colineales; union por columna/mocheta; esquina al muro mas largo
A41: SÓTANO | B41: SOT-38 | C41: Muro de contención de 30cm | D41: 0.3 | E41: 1.739 | F41: 7.885 | G41: 1.739 | H41: 8.676 | I41: 0.791 | J41: 0 | K41: 0 | L41: =I41-K41 | M41: General | N41: =VLOOKUP(A41&"|"&M41,PARAMETROS!$A$4:$B$9,2,FALSE) | O41: =I41*N41 | P41: =K41*PARAMETROS!$B$10 | Q41: =O41-P41 | R41: S-1 CIMENTACION Y DETALLES | S41: Corrida de blocks colineales; union por columna/mocheta; esquina al muro mas largo
...

Sheet OBSERVACIONES Y RFI
A1: No. | B1: Tema | C1: Descripcion | D1: Impacto
A2: RFI-04 | B2: Ventanas | C2: Los emplantillados no muestran ventanas: el area neta solo descuenta puertas (como V2). El libro a mano descuenta puertas y ventanas. Falta el plano de arquitectura o cortes con ventanas. | D2: Area neta sobrestimada en el area de ventanas
A3: OBS-05 | B3: Alturas | C3: Verificadas con S-1 (detalles MC1 y CC1), S-2 (niveles de losa), S-7 y S-8 (secciones). Ver PARAMETROS. La altura de puerta 2.10 sigue como supuesto.
A4: OBS-06 | B4: Ejes | C4: Ejes ubicados registrando el PDF S-1 contra el DXF (82% de esquinas de block coinciden a menos de 3 cm): eje 5 x=-2.60, eje 6 x=1.81, eje C y=1.33, eje A y=8.84. Muros que cruzan los ejes 5 o 6 se parten.
A5: RFI-07 | B5: Contencion bajo losa NPT 0.00 | C5: El detalle MC1 rotula NPT -0.35/0.00 con 3.50 m sobre piso; se usa 4.30 en toda la contencion. Si bajo la losa a 0.00 sube a 3.85, sumar 0.35 m en ~10 ml. | D5: ~3.5 m2
A6: OBS-07 | B6: Contencion = doble hilada | C6: Dos corridas de block de 15 separadas 0.12-0.19 m = muro de contencion de 30 cm (criterio de la oficina).
A7: OBS-08 | B7: Union por columnas | C7: Huecos entre corridas colineales <=0.62 m, o con columna/mocheta dibujada o etiqueta C# a menos de 1 m, se cuentan como muro corrido (la columna se descuenta despues en 'solo block'). Huecos 0.62-2.05 m sin columna = vano de puerta.
A8: OBS-09 | B8: Esquinas | C8: En L el muro mas largo llega a la cara exterior y el corto a la cara interior; en T el muro llega a la cara del que cruza. Traslape residual: SOT 0.34 m2, N1 0.20 m2, N2 0.10 m2 en planta. | D8: <0.2%
A9: OBS-10 | B9: Perimetral N1 | C9: Los dos tramos de 15 cm de mas de 30 m en S-3 se clasifican como muro perimetral (35.65 + 33.42 ml), igual que V2 (69.00).
A10: OBS-11 | B10: Alcance | C10: Esta hoja cuantifica muro (longitud, area bruta, vanos, area neta). No incluye 'solo block' (descuento de columnas, mochetas y soleras), pines ni soleras: pendiente si se pide.
